Workbook

Sheet Raw_data
A1: Order ID | B1: Customer ID | C1: Restaurant ID | D1: Order Date and Time | E1: Delivery Date and Time | F1: Order Value | G1: Delivery Fee | H1: Payment Method | I1: Discounts and Offers | J1: Commission Fee | K1: Payment Processing Fee | L1: Refunds/Chargebacks
A2: 1 | B2: C8270 | C2: R2924 | D2: 45323.05 | E2: 45323.111 | F2: 1914 | G2: 0 | H2: Credit Card | I2: 5% on App | J2: 150 | K2: 47 | L2: 0
A3: 2 | B3: C1860 | C3: R2054 | D3: 45324.924 | E3: 45324.949 | F3: 986 | G3: 40 | H3: Digital Wallet | I3: 0.1 | J3: 198 | K3: 23 | L3: 0
A4: 3 | B4: C6390 | C4: R2870 | D4: 45322.246 | E4: 45322.287 | F4: 937 | G4: 30 | H4: Cash on Delivery | I4: 15% New User | J4: 195 | K4: 45 | L4: 0
A5: 4 | B5: C6191 | C5: R2642 | D5: 45307.953 | E5: 45307.985 | F5: 1463 | G5: 50 | H5: Cash on Delivery | I5: None | J5: 146 | K5: 27 | L5: 0
A6: 5 | B6: C6734 | C6: R2799 | D6: 45320.055 | E6: 45320.117 | F6: 1992 | G6: 30 | H6: Cash on Delivery | I6: 50 off Promo | J6: 130 | K6: 50 | L6: 0
A7: 6 | B7: C7265 | C7: R2777 | D7: 45316.192 | E7: 45316.228 | F7: 439 | G7: 20 | H7: Cash on Delivery | I7: 0.1 | J7: 92 | K7: 27 | L7: 150
A8: 7 | B8: C1466 | C8: R2457 | D8: 45303.997 | E8: 45304.034 | F8: 303 | G8: 30 | H8: Digital Wallet | I8: 5% on App | J8: 144 | K8: 12 | L8: 50
A9: 8 | B9: C5426 | C9: R2978 | D9: 45317.949 | E9: 45318.025 | F9: 260 | G9: 0 | H9: Credit Card | I9: 0.1 | J9: 55 | K9: 19 | L9: 0
A10: 9 | B10: C6578 | C10: R2877 | D10: 45293.771 | E10: 45293.85 | F10: 1663 | G10: 40 | H10: Cash on Delivery | I10: 5% on App | J10: 116 | K10: 48 | L10: 0
A11: 10 | B11: C9322 | C11: R2161 | D11: 45296.035 | E11: 45296.09 | F11: 491 | G11: 40 | H11: Digital Wallet | I11: 0.1 | J11: 189 | K11: 10 | L11: 0
A12: 11 | B12: C2685 | C12: R2379 | D12: 45292.71 | E12: 45292.765 | F12: 868 | G12: 0 | H12: Cash on Delivery | I12: 5% on App | J12: 149 | K12: 36 | L12: 0
A13: 12 | B13: C1769 | C13: R2992 | D13: 45300.719 | E13: 45300.747 | F13: 1800 | G13: 20 | H13: Credit Card | I13: 15% New User | J13: 61 | K13: 36 | L13: 0
A14: 13 | B14: C7949 | C14: R2086 | D14: 45296.697 | E14: 45296.756 | F14: 674 | G14: 0 | H14: Cash on Delivery | I14: None | J14: 115 | K14: 20 | L14: 0
A15: 14 | B15: C3433 | C15: R2054 | D15: 45326.784 | E15: 45326.853 | F15: 633 | G15: 30 | H15: Digital Wallet | I15: 15% New User | J15: 51 | K15: 14 | L15: 50
A16: 15 | B16: C6311 | C16: R2475 | D16: 45325.035 | E16: 45325.084 | F16: 1193 | G16: 0 | H16: Credit Card | I16: None | J16: 192 | K16: 16 | L16: 0
A17: 16 | B17: C6051 | C17: R2799 | D17: 45306.866 | E17: 45306.913 | F17: 992 | G17: 0 | H17: Digital Wallet | I17: 15% New User | J17: 200 | K17: 28 | L17: 0
A18: 17 | B18: C7420 | C18: R2177 | D18: 45326.742 | E18: 45326.81 | F18: 504 | G18: 20 | H18: Credit Card | I18: 15% New User | J18: 130 | K18: 38 | L18: 0
A19: 18 | B19: C2184 | C19: R2390 | D19: 45304.654 | E19: 45304.708 | F19: 707 | G19: 30 | H19: Credit Card | I19: 0.1 | J19: 184 | K19: 24 | L19: 0
A20: 19 | B20: C5555 | C20: R2348 | D20: 45322.727 | E20: 45322.787 | F20: 1798 | G20: 50 | H20: Credit Card | I20: 50 off Promo | J20: 191 | K20: 44 | L20: 0
A21: 20 | B21: C4385 | C21: R2007 | D21: 45304.065 | E21: 45304.099 | F21: 1714 | G21: 50 | H21: Cash on Delivery | I21: 5% on App | J21: 119 | K21: 46 | L21: 100
A22: 21 | B22: C7396 | C22: R2832 | D22: 45318.614 | E22: 45318.691 | F22: 1640 | G22: 40 | H22: Digital Wallet | I22: 5% on App | J22: 164 | K22: 21 | L22: 0
A23: 22 | B23: C9666 | C23: R2312 | D23: 45296.43 | E23: 45296.464 | F23: 927 | G23: 0 | H23: Digital Wallet | I23: 5% on App | J23: 137 | K23: 39 | L23: 0
A24: 23 | B24: C3558 | C24: R2758 | D24: 45314.125 | E24: 45314.156 | F24: 1243 | G24: 40 | H24: Digital Wallet | I24: None | J24: 55 | K24: 29 | L24: 100
A25: 24 | B25: C8849 | C25: R2834 | D25: 45329.699 | E25: 45329.767 | F25: 1937 | G25: 20 | H25: Credit Card | I25: 5% on App | J25: 76 | K25: 46 | L25: 0
A26: 25 | B26: C3047 | C26: R2983 | D26: 45304.366 | E26: 45304.439 | F26: 789 | G26: 50 | H26: Cash on Delivery | I26: 5% on App | J26: 131 | K26: 12 | L26: 0
A27: 26 | B27: C3747 | C27: R2982 | D27: 45303.108 | E27: 45303.164 | F27: 1811 | G27: 0 | H27: Credit Card | I27: 0.1 | J27: 137 | K27: 18 | L27: 0
A28: 27 | B28: C1189 | C28: R2442 | D28: 45302.692 | E28: 45302.765 | F28: 1001 | G28: 20 | H28: Digital Wallet | I28: 15% New User | J28: 169 | K28: 50 | L28: 0
A29: 28 | B29: C3734 | C29: R2766 | D29: 45325.177 | E29: 45325.24 | F29: 1340 | G29: 20 | H29: Cash on Delivery | I29: 5% on App | J29: 73 | K29: 48 | L29: 100
A30: 29 | B30: C4005 | C30: R2327 | D30: 45308.959 | E30: 45309.039 | F30: 155 | G30: 0 | H30: Cash on Delivery | I30: 50 off Promo | J30: 151 | K30: 35 | L30: 0
A31: 30 | B31: C5658 | C31: R2053 | D31: 45327.917 | E31: 45327.963 | F31: 465 | G31: 20 | H31: Cash on Delivery | I31: 5% on App | J31: 83 | K31: 11 | L31: 0
A32: 31 | B32: C2899 | C32: R2760 | D32: 45320.567 | E32: 45320.591 | F32: 1822 | G32: 0 | H32: Digital Wallet | I32: None | J32: 96 | K32: 32 | L32: 0
A33: 32 | B33: C8734 | C33: R2238 | D33: 45294.472 | E33: 45294.541 | F33: 1627 | G33: 0 | H33: Cash on Delivery | I33: None | J33: 73 | K33: 32 | L33: 0
A34: 33 | B34: C2267 | C34: R2228 | D34: 45323.17 | E34: 45323.208 | F34: 1867 | G34: 30 | H34: Cash on Delivery | I34: None | J34: 114 | K34: 30 | L34: 50
A35: 34 | B35: C2528 | C35: R2578 | D35: 45314.486 | E35: 45314.512 | F35: 1890 | G35: 40 | H35: Credit Card | I35: 5% on App | J35: 67 | K35: 25 | L35: 0
A36: 35 | B36: C4556 | C36: R2050 | D36: 45318.775 | E36: 45318.846 | F36: 554 | G36: 20 | H36: Credit Card | I36: 0.1 | J36: 93 | K36: 18 | L36: 0
A37: 36 | B37: C4890 | C37: R2608 | D37: 45295.45 | E37: 45295.473 | F37: 203 | G37: 20 | H37: Cash on Delivery | I37: 50 off Promo | J37: 125 | K37: 22 | L37: 0
A38: 37 | B38: C9838 | C38: R2603 | D38: 45295.673 | E38: 45295.708 | F38: 176 | G38: 30 | H38: Cash on Delivery | I38: 5% on App | J38: 106 | K38: 37 | L38: 0
A39: 38 | B39: C6393 | C39: R2263 | D39: 45306.254 | E39: 45306.296 | F39: 329 | G39: 30 | H39: Credit Card | I39: 0.1 | J39: 156 | K39: 36 | L39: 0
A40: 39 | B40: C9792 | C40: R2417 | D40: 45327.721 | E40: 45327.756 | F40: 1381 | G40: 30 | H40: Credit Card | I40: 0.1 | J40: 173 | K40: 26 | L40: 0
...

Sheet Data_prep
A1: Order_ID | B1: Customer_ID | C1: Restaurant_ID | D1: Order_date | E1: Delivery_date | F1: Delivery_time | G1: Order_value | H1: Delivery_fee | I1: Payment_method | J1: Discounts_and_offers | K1: Commission_fee | L1: Payment_processing_fee | M1: Refunds/chargebacks | N1: Restaurant_profit | O1: Platform_profit | P1: Customer_cost | Q1: Orders_count_customer | R1: Orders_count_restaurant
A2: =Raw_data!A2 -> 1 | B2: =Raw_data!B2 -> C8270 | C2: =Raw_data!C2 -> R2924 | D2: =Raw_data!D2 -> 45323.05 | E2: =Raw_data!E2 -> 45323.111 | F2: =E2-D2 -> 0.061111111 | G2: =Raw_data!F2 -> 1914 | H2: =Raw_data!G2 -> 0 | I2: =Raw_data!H2 -> Credit Card | J2: =IF(Raw_data!I2=0.1,"10%",Raw_data!I2) -> 5% on App | K2: =Raw_data!J2 -> 150 | L2: =Raw_data!K2 -> 47 | M2: =Raw_data!L2 -> 0 | N2: =G2-K2-L2 -> 1717 | O2: =K2+L2-M2 -> 197 | P2: =G2+H2 -> 1914 | Q2: =COUNTIF(B$2:B$1001,B2) -> 1 | R2: =COUNTIF(C$2:C$1001,C2) -> 1
A3: =Raw_data!A3 -> 2 | B3: =Raw_data!B3 -> C1860 | C3: =Raw_data!C3 -> R2054 | D3: =Raw_data!D3 -> 45324.924 | E3: =Raw_data!E3 -> 45324.949 | F3: =E3-D3 -> 0.024305556 | G3: =Raw_data!F3 -> 986 | H3: =Raw_data!G3 -> 40 | I3: =Raw_data!H3 -> Digital Wallet | J3: =IF(Raw_data!I3=0.1,"10%",Raw_data!I3) -> 10% | K3: =Raw_data!J3 -> 198 | L3: =Raw_data!K3 -> 23 | M3: =Raw_data!L3 -> 0 | N3: =G3-K3-L3 -> 765 | O3: =K3+L3-M3 -> 221 | P3: =G3+H3 -> 1026 | Q3: =COUNTIF(B$2:B$1001,B3) -> 1 | R3: =COUNTIF(C$2:C$1001,C3) -> 3
A4: =Raw_data!A4 -> 3 | B4: =Raw_data!B4 -> C6390 | C4: =Raw_data!C4 -> R2870 | D4: =Raw_data!D4 -> 45322.246 | E4: =Raw_data!E4 -> 45322.287 | F4: =E4-D4 -> 0.040277778 | G4: =Raw_data!F4 -> 937 | H4: =Raw_data!G4 -> 30 | I4: =Raw_data!H4 -> Cash on Delivery | J4: =IF(Raw_data!I4=0.1,"10%",Raw_data!I4) -> 15% New User | K4: =Raw_data!J4 -> 195 | L4: =Raw_data!K4 -> 45 | M4: =Raw_data!L4 -> 0 | N4: =G4-K4-L4 -> 697 | O4: =K4+L4-M4 -> 240 | P4: =G4+H4 -> 967 | Q4: =COUNTIF(B$2:B$1001,B4) -> 1 | R4: =COUNTIF(C$2:C$1001,C4) -> 2
A5: =Raw_data!A5 -> 4 | B5: =Raw_data!B5 -> C6191 | C5: =Raw_data!C5 -> R2642 | D5: =Raw_data!D5 -> 45307.953 | E5: =Raw_data!E5 -> 45307.985 | F5: =E5-D5 -> 0.031944444 | G5: =Raw_data!F5 -> 1463 | H5: =Raw_data!G5 -> 50 | I5: =Raw_data!H5 -> Cash on Delivery | J5: =IF(Raw_data!I5=0.1,"10%",Raw_data!I5) -> None | K5: =Raw_data!J5 -> 146 | L5: =Raw_data!K5 -> 27 | M5: =Raw_data!L5 -> 0 | N5: =G5-K5-L5 -> 1290 | O5: =K5+L5-M5 -> 173 | P5: =G5+H5 -> 1513 | Q5: =COUNTIF(B$2:B$1001,B5) -> 1 | R5: =COUNTIF(C$2:C$1001,C5) -> 3
A6: =Raw_data!A6 -> 5 | B6: =Raw_data!B6 -> C6734 | C6: =Raw_data!C6 -> R2799 | D6: =Raw_data!D6 -> 45320.055 | E6: =Raw_data!E6 -> 45320.117 | F6: =E6-D6 -> 0.061805556 | G6: =Raw_data!F6 -> 1992 | H6: =Raw_data!G6 -> 30 | I6: =Raw_data!H6 -> Cash on Delivery | J6: =IF(Raw_data!I6=0.1,"10%",Raw_data!I6) -> 50 off Promo | K6: =Raw_data!J6 -> 130 | L6: =Raw_data!K6 -> 50 | M6: =Raw_data!L6 -> 0 | N6: =G6-K6-L6 -> 1812 | O6: =K6+L6-M6 -> 180 | P6: =G6+H6 -> 2022 | Q6: =COUNTIF(B$2:B$1001,B6) -> 1 | R6: =COUNTIF(C$2:C$1001,C6) -> 3
A7: =Raw_data!A7 -> 6 | B7: =Raw_data!B7 -> C7265 | C7: =Raw_data!C7 -> R2777 | D7: =Raw_data!D7 -> 45316.192 | E7: =Raw_data!E7 -> 45316.228 | F7: =E7-D7 -> 0.035416667 | G7: =Raw_data!F7 -> 439 | H7: =Raw_data!G7 -> 20 | I7: =Raw_data!H7 -> Cash on Delivery | J7: =IF(Raw_data!I7=0.1,"10%",Raw_data!I7) -> 10% | K7: =Raw_data!J7 -> 92 | L7: =Raw_data!K7 -> 27 | M7: =Raw_data!L7 -> 150 | N7: =G7-K7-L7 -> 320 | O7: =K7+L7-M7 -> -31 | P7: =G7+H7 -> 459 | Q7: =COUNTIF(B$2:B$1001,B7) -> 1 | R7: =COUNTIF(C$2:C$1001,C7) -> 2
A8: =Raw_data!A8 -> 7 | B8: =Raw_data!B8 -> C1466 | C8: =Raw_data!C8 -> R2457 | D8: =Raw_data!D8 -> 45303.997 | E8: =Raw_data!E8 -> 45304.034 | F8: =E8-D8 -> 0.036805556 | G8: =Raw_data!F8 -> 303 | H8: =Raw_data!G8 -> 30 | I8: =Raw_data!H8 -> Digital Wallet | J8: =IF(Raw_data!I8=0.1,"10%",Raw_data!I8) -> 5% on App | K8: =Raw_data!J8 -> 144 | L8: =Raw_data!K8 -> 12 | M8: =Raw_data!L8 -> 50 | N8: =G8-K8-L8 -> 147 | O8: =K8+L8-M8 -> 106 | P8: =G8+H8 -> 333 | Q8: =COUNTIF(B$2:B$1001,B8) -> 1 | R8: =COUNTIF(C$2:C$1001,C8) -> 1
A9: =Raw_data!A9 -> 8 | B9: =Raw_data!B9 -> C5426 | C9: =Raw_data!C9 -> R2978 | D9: =Raw_data!D9 -> 45317.949 | E9: =Raw_data!E9 -> 45318.025 | F9: =E9-D9 -> 0.076388889 | G9: =Raw_data!F9 -> 260 | H9: =Raw_data!G9 -> 0 | I9: =Raw_data!H9 -> Credit Card | J9: =IF(Raw_data!I9=0.1,"10%",Raw_data!I9) -> 10% | K9: =Raw_data!J9 -> 55 | L9: =Raw_data!K9 -> 19 | M9: =Raw_data!L9 -> 0 | N9: =G9-K9-L9 -> 186 | O9: =K9+L9-M9 -> 74 | P9: =G9+H9 -> 260 | Q9: =COUNTIF(B$2:B$1001,B9) -> 1 | R9: =COUNTIF(C$2:C$1001,C9) -> 1
A10: =Raw_data!A10 -> 9 | B10: =Raw_data!B10 -> C6578 | C10: =Raw_data!C10 -> R2877 | D10: =Raw_data!D10 -> 45293.771 | E10: =Raw_data!E10 -> 45293.85 | F10: =E10-D10 -> 0.079166667 | G10: =Raw_data!F10 -> 1663 | H10: =Raw_data!G10 -> 40 | I10: =Raw_data!H10 -> Cash on Delivery | J10: =IF(Raw_data!I10=0.1,"10%",Raw_data!I10) -> 5% on App | K10: =Raw_data!J10 -> 116 | L10: =Raw_data!K10 -> 48 | M10: =Raw_data!L10 -> 0 | N10: =G10-K10-L10 -> 1499 | O10: =K10+L10-M10 -> 164 | P10: =G10+H10 -> 1703 | Q10: =COUNTIF(B$2:B$1001,B10) -> 1 | R10: =COUNTIF(C$2:C$1001,C10) -> 1
A11: =Raw_data!A11 -> 10 | B11: =Raw_data!B11 -> C9322 | C11: =Raw_data!C11 -> R2161 | D11: =Raw_data!D11 -> 45296.035 | E11: =Raw_data!E11 -> 45296.09 | F11: =E11-D11 -> 0.055555556 | G11: =Raw_data!F11 -> 491 | H11: =Raw_data!G11 -> 40 | I11: =Raw_data!H11 -> Digital Wallet | J11: =IF(Raw_data!I11=0.1,"10%",Raw_data!I11) -> 10% | K11: =Raw_data!J11 -> 189 | L11: =Raw_data!K11 -> 10 | M11: =Raw_data!L11 -> 0 | N11: =G11-K11-L11 -> 292 | O11: =K11+L11-M11 -> 199 | P11: =G11+H11 -> 531 | Q11: =COUNTIF(B$2:B$1001,B11) -> 1 | R11: =COUNTIF(C$2:C$1001,C11) -> 2
A12: =Raw_data!A12 -> 11 | B12: =Raw_data!B12 -> C2685 | C12: =Raw_data!C12 -> R2379 | D12: =Raw_data!D12 -> 45292.71 | E12: =Raw_data!E12 -> 45292.765 | F12: =E12-D12 -> 0.054861111 | G12: =Raw_data!F12 -> 868 | H12: =Raw_data!G12 -> 0 | I12: =Raw_data!H12 -> Cash on Delivery | J12: =IF(Raw_data!I12=0.1,"10%",Raw_data!I12) -> 5% on App | K12: =Raw_data!J12 -> 149 | L12: =Raw_data!K12 -> 36 | M12: =Raw_data!L12 -> 0 | N12: =G12-K12-L12 -> 683 | O12: =K12+L12-M12 -> 185 | P12: =G12+H12 -> 868 | Q12: =COUNTIF(B$2:B$1001,B12) -> 1 | R12: =COUNTIF(C$2:C$1001,C12) -> 2
A13: =Raw_data!A13 -> 12 | B13: =Raw_data!B13 -> C1769 | C13: =Raw_data!C13 -> R2992 | D13: =Raw_data!D13 -> 45300.719 | E13: =Raw_data!E13 -> 45300.747 | F13: =E13-D13 -> 0.027777778 | G13: =Raw_data!F13 -> 1800 | H13: =Raw_data!G13 -> 20 | I13: =Raw_data!H13 -> Credit Card | J13: =IF(Raw_data!I13=0.1,"10%",Raw_data!I13) -> 15% New User | K13: =Raw_data!J13 -> 61 | L13: =Raw_data!K13 -> 36 | M13: =Raw_data!L13 -> 0 | N13: =G13-K13-L13 -> 1703 | O13: =K13+L13-M13 -> 97 | P13: =G13+H13 -> 1820 | Q13: =COUNTIF(B$2:B$1001,B13) -> 1 | R13: =COUNTIF(C$2:C$1001,C13) -> 1
... A1001: =Raw_data!A1001 -> 1000 | B1001: =Raw_data!B1001 -> C4335 | C1001: =Raw_data!C1001 -> R2890 | D1001: =Raw_data!D1001 -> 45299.616 | E1001: =Raw_data!E1001 -> 45299.653 | F1001: =E1001-D1001 -> 0.036805556 | G1001: =Raw_data!F1001 -> 1657 | H1001: =Raw_data!G1001 -> 20 | I1001: =Raw_data!H1001 -> Digital Wallet | J1001: =IF(Raw_data!I1001=0.1,"10%",Raw_data!I1001) -> 15% New User | K1001: =Raw_data!J1001 -> 180 | L1001: =Raw_data!K1001 -> 27 | M1001: =Raw_data!L1001 -> 100 | N1001: =G1001-K1001-L1001 -> 1450 | O1001: =K1001+L1001-M1001 -> 107 | P1001: =G1001+H1001 -> 1677 | Q1001: =COUNTIF(B$2:B$1001,B1001) -> 1 | R1001: =COUNTIF(C$2:C$1001,C1001) -> 3

Sheet Pivot_summary_restaurants
A1: Which restaurants have the highest number of orders? *At least 3 orders. | D1: Which restaurants have the highest revenue? Top 10. | G1: Which restaurants have the highest profit? Top 10. | J1: Which restaurants are paying the lowest platform costs/revenue rate? Top 10. *At least 3 orders. | M1: Which restaurants are paying the highest platform costs/revenue rate? Top 10. *At least 3 orders. | P1: Which restaurants present the lowest average delivery times? Top 10. *At least 3 orders. | S1: Which restaurants present the highest average delivery times? Top 10. *At least 3 orders. | V1: Which restaurants present the highest refund rate? Top 12. *At least 3 orders.
A3: Orders_filter | B3: (Multiple Items) | D3: Orders_filter | E3: (All) | G3: Orders_filter | H3: (All) | J3: Orders_filter | K3: (Multiple Items) | M3: Orders_filter | N3: (Multiple Items) | P3: Orders_filter | Q3: (Multiple Items) | S3: Orders_filter | T3: (Multiple Items) | V3: Orders_filter | W3: (Multiple Items)
A5: Restaurant | B5: Orders | D5: Restaurant | E5: Revenue | G5: Restaurant | H5: Profit | J5: Restaurant | K5: Rate | M5: Restaurant | N5: Rate | P5: Restaurant | Q5: Delivery time | S5: Restaurant | T5: Delivery time | V5: Restaurant | W5: Refunds | X5: Average
A6: R2317 | B6: 6 | D6: R2726 | E6: 6794 | G6: R2726 | H6: 5985 | J6: R2747 | K6: 0.068793236 | M6: R2915 | N6: 0.40143369 | P6: R2284 | Q6: 0.025694444 | S6: R2039 | T6: 0.071354167 | V6: R2570 | W6: 550 | X6: 137.5
A7: R2083 | B7: 5 | D7: R2083 | E7: 6291 | G7: R2083 | H7: 5599 | J7: R2300 | K7: 0.081690141 | M7: R2250 | N7: 0.33936652 | P7: R2536 | Q7: 0.029398148 | S7: R2317 | T7: 0.068981481 | V7: R2334 | W7: 400 | X7: 133.33333
A8: R2016 | B8: 5 | D8: R2933 | E8: 6049 | G8: R2933 | H8: 5547 | J8: R2933 | K8: 0.082988924 | M8: R2358 | N8: 0.30307577 | P8: R2267 | Q8: 0.03125 | S8: R2956 | T8: 0.068055556 | V8: R2287 | W8: 300 | X8: 100
A9: R2804 | B9: 5 | D9: R2329 | E9: 5398 | G9: R2329 | H9: 4894 | J9: R2704 | K9: 0.084329767 | M9: R2956 | N9: 0.27524308 | P9: R2454 | Q9: 0.032638889 | S9: R2525 | T9: 0.068055556 | V9: R2010 | W9: 250 | X9: 83.333333
A10: R2726 | B10: 5 | D10: R2355 | E10: 5320 | G10: R2747 | H10: 4846 | J10: R2329 | K10: 0.093367914 | M10: R2152 | N10: 0.25931034 | P10: R2520 | Q10: 0.032638889 | S10: R2713 | T10: 0.067824074 | V10: R2169 | W10: 250 | X10: 83.333333
A11: R2523 | B11: 5 | D11: R2747 | E11: 5204 | G11: R2355 | H11: 4702 | J11: R2010 | K11: 0.096824167 | M11: R2920 | N11: 0.24129475 | P11: R2362 | Q11: 0.035416667 | S11: R2793 | T11: 0.065509259 | V11: R2816 | W11: 250 | X11: 83.333333
A12: R2738 | B12: 4 | D12: R2317 | E12: 5141 | G12: R2317 | H12: 4419 | J12: R2989 | K12: 0.10200457 | M12: R2515 | N12: 0.23280423 | P12: R2920 | Q12: 0.03587963 | S12: R2334 | T12: 0.065277778 | V12: R2129 | W12: 200 | X12: 66.666667
A13: R2773 | B13: 4 | D13: R2006 | E13: 4933 | G13: R2704 | H13: 4365 | J13: R2343 | K13: 0.103262 | M13: R2223 | N13: 0.21539123 | P13: R2954 | Q13: 0.03587963 | S13: R2006 | T13: 0.064756944 | V13: R2890 | W13: 200 | X13: 66.666667
A14: R2972 | B14: 4 | D14: R2804 | E14: 4868 | G14: R2343 | H14: 4316 | J14: R2552 | K14: 0.10441176 | M14: R2458 | N14: 0.20901126 | P14: R2119 | Q14: 0.0375 | S14: R2038 | T14: 0.064583333 | V14: R2028 | W14: 250 | X14: 62.5
A15: R2933 | B15: 4 | D15: R2343 | E15: 4813 | G15: R2552 | H15: 4263 | J15: R2957 | K15: 0.10512893 | M15: R2225 | N15: 0.20122993 | P15: R2570 | Q15: 0.039409722 | S15: R2609 | T15: 0.06412037 | V15: R2773 | W15: 250 | X15: 62.5
A16: R2038 | B16: 4 | V16: R2972 | W16: 250 | X16: 62.5
A17: R2699 | B17: 4 | V17: R2225 | W17: 250 | X17: 62.5
A18: R2348 | B18: 4
A19: R2570 | B19: 4
A20: R2225 | B20: 4
A21: R2865 | B21: 4
A22: R2039 | B22: 4
A23: R2006 | B23: 4
A24: R2028 | B24: 4
A25: R2400 | B25: 4
A26: R2355 | B26: 4
A27: R2520 | B27: 4
A28: R2309 | B28: 3
A29: R2054 | B29: 3
... A82: R2515 | B82: 3

Sheet Pivot_summary_customers
A1: Which clients buy the most? Top 10. | E1: Which clients observe the lowest delivery times? Top 10. *At least 2 orders. | H1: Which clients observe the highest delivery times? Top 10. *At least 2 orders. | K1: Which clients present the highest refund rate? Top 5.
A3: Orders_filter | B3: (All) | E3: Orders_filter | F3: (Multiple Items) | H3: Orders_filter | I3: (Multiple Items) | K3: Orders_filter | L3: (All)
A5: Client | B5: Total_bought | C5: Purchases | E5: Client | F5: Delivery time | H5: Client | I5: Delivery time | K5: Client | L5: Refunds | M5: Average | N5: Purchases
A6: C7949 | B6: 3870 | C6: 3 | E6: C4072 | F6: 0.027083333 | H6: C9905 | I6: 0.074652778 | K6: C1698 | L6: 300 | M6: 150 | N6: 2
A7: C3832 | B7: 3768 | C7: 2 | E7: C2693 | F7: 0.027430556 | H7: C5380 | I7: 0.073958333 | K7: C5380 | L7: 250 | M7: 125 | N7: 2
A8: C8266 | B8: 3703 | C8: 2 | E8: C6592 | F8: 0.028472222 | H8: C9702 | I8: 0.067361111 | K8: C7316 | L8: 250 | M8: 125 | N8: 2
A9: C5555 | B9: 3664 | C9: 2 | E9: C1009 | F9: 0.030208333 | H9: C7941 | I9: 0.067013889 | K9: C4627 | L9: 250 | M9: 125 | N9: 2
A10: C5146 | B10: 3361 | C10: 2 | E10: C3832 | F10: 0.031597222 | H10: C3327 | I10: 0.066319444 | K10: C2365 | L10: 200 | M10: 100 | N10: 2
A11: C8560 | B11: 3315 | C11: 2 | E11: C7316 | F11: 0.033333333 | H11: C5555 | I11: 0.065625
A12: C6732 | B12: 3220 | C12: 2 | E12: C4177 | F12: 0.034722222 | H12: C6977 | I12: 0.064930556
A13: C5000 | B13: 3162 | C13: 2 | E13: C8392 | F13: 0.035069444 | H13: C1876 | I13: 0.063194444
A14: C1009 | B14: 3122 | C14: 2 | E14: C7938 | F14: 0.035416667 | H14: C2365 | I14: 0.061805556
A15: C6486 | B15: 3069 | C15: 2 | E15: C2062 | F15: 0.036458333 | H15: C9120 | I15: 0.061805556

Sheet Pivot_summary_platform
A1: Which promotions/discounts generate the highest revenue? | E1: Which delivery fees generate the highest revenue? | I1: Which restaurants generate more profit for the platform? Top 10. | M1: Which clients generate more profit for the platform? Top 10. | Q1: Which payment methods are more common, and how much revenue do they produce?
A3: Offer | B3: Revenue | C3: Orders | E3: Delivery fee | F3: Revenue | G3: Orders | I3: Restaurant | J3: Profit | K3: Orders | M3: Client | N3: Profit | O3: Orders | Q3: Payment method | R3: Revenue | S3: Orders
A4: 10% | B4: 245525 | C4: 233 | E4: 30 | F4: 231128 | G4: 208 | I4: R2523 | J4: 795 | K4: 5 | M4: C7949 | N4: 492 | O4: 3 | Q4: Cash on Delivery | R4: 374669 | S4: 357
A5: 50 off Promo | B5: 220036 | C5: 201 | E5: 40 | F5: 225962 | G5: 207 | I5: R2726 | J5: 759 | K5: 5 | M5: C7287 | N5: 418 | O5: 2 | Q5: Credit Card | R5: 361208 | S5: 337
A6: 15% New User | B6: 199598 | C6: 198 | E6: 20 | F6: 204626 | G6: 195 | I6: R2006 | J6: 647 | K6: 4 | M6: C7938 | N6: 415 | O6: 3 | Q6: Digital Wallet | R6: 318092 | S6: 306
A7: 5% on App | B7: 194953 | C7: 183 | E7: 50 | F7: 201443 | G7: 204 | I7: R2083 | J7: 642 | K7: 5 | M7: C6732 | N7: 413 | O7: 2
A8: None | B8: 193857 | C8: 185 | E8: 0 | F8: 190810 | G8: 186 | I8: R2039 | J8: 584 | K8: 4 | M8: C8186 | N8: 399 | O8: 2
I9: R2222 | J9: 580 | K9: 3 | M9: C5555 | N9: 395 | O9: 2
I10: R2355 | J10: 568 | K10: 4 | M10: C6592 | N10: 361 | O10: 2
I11: R2799 | J11: 562 | K11: 3 | M11: C8400 | N11: 350 | O11: 2
I12: R2038 | J12: 561 | K12: 4 | M12: C2184 | N12: 350 | O12: 2
I13: R2738 | J13: 561 | K13: 4 | M13: C7190 | N13: 341 | O13: 2

Sheet Dashboard_platform
A1: TOTAL SALES | E1: TOTAL PROFIT (PLATFORM) | I1: NUMBER OF CUSTOMERS REACHED | M1: NUMBER OF REGISTERED RESTAURANTS | Q1: NUMBER OF ORDERS PROCESSED | U1: TOTAL REFUND RATE | Y1: AVERAGE DELIVERY TIME
A2: =SUM(Data_prep_table[Order_value]) -> 1053969 | E2: =SUM(Data_prep_table[Platform_profit]) -> 128522 | I2: =COUNTIF(Data_prep_table[Orders_count_customer],1)+COUNTIF(Data_prep_table[Orders_count_customer],2)/2+COUNTIF(Data_prep_table[Orders_count_customer],3)/3 -> 947 | M2: =COUNTIF(Data_prep_table[Orders_count_restaurant],1)+COUNTIF(Data_prep_table[Orders_count_restaurant],2)/2+COUNTIF(Data_prep_table[Orders_count_restaurant],3)/3+COUNTIF(Data_prep_table[Orders_count_restaurant],4)/4+COUNTIF(Data_prep_table[Orders_count_restaurant],5)/5+COUNTIF(Data_prep_table[Orders_count_restaurant],6)/6 -> 621 | Q2: =COUNT(Data_prep_table[Order_ID]) -> 1000 | U2: =SUM(Data_prep_table[Refunds/chargebacks])/SUM(Data_prep_table[Order_value],Data_prep_table[Delivery_fee]) -> 0.026141038 | Y2: =AVERAGE(Data_prep_table[Delivery_time]) -> 0.05109375
C4: TOP 6 RESTAURANTS WITH MORE ORDERS | H4: TOP 5 RESTAURANTS WITH MORE REVENUE | M4: TOP 5 RESTAURANTS WITH MORE PROFIT | R4: TOP 5 RESTAURANTS WITH THE BEST AVERAGE DELIVERY TIME | W4: TOP 6 RESTAURANTS WITH THE WORST AVERAGE REFUND
C5: Restaurant | E5: Orders | H5: Restaurant | J5: Revenue | M5: Restaurant | O5: Profit | R5: Restaurant | T5: Delivery time | W5: Restaurant | Y5: Refund
C6: =Pivot_summary_restaurants!A6 -> R2317 | E6: =GETPIVOTDATA("Restaurant_ID",Pivot_summary_restaurants!$A$5,"Restaurant_ID","R2317") -> 6 | H6: =Pivot_summary_restaurants!D6 -> R2726 | J6: =GETPIVOTDATA("Order_value",Pivot_summary_restaurants!$D$5,"Restaurant_ID","R2726") -> 6794 | M6: =Pivot_summary_restaurants!G6 -> R2726 | O6: =GETPIVOTDATA("Restaurant_profit",Pivot_summary_restaurants!$G$5,"Restaurant_ID","R2726") -> 5985 | R6: =Pivot_summary_restaurants!P6 -> R2284 | T6: =GETPIVOTDATA("Delivery_time",Pivot_summary_restaurants!$P$5,"Restaurant_ID","R2284") -> 0.025694444 | W6: =Pivot_summary_restaurants!V6 -> R2570 | Y6: =GETPIVOTDATA("Average",Pivot_summary_restaurants!$V$5,"Restaurant_ID","R2570") -> 137.5
C7: =Pivot_summary_restaurants!A7 -> R2083 | E7: =GETPIVOTDATA("Restaurant_ID",Pivot_summary_restaurants!$A$5,"Restaurant_ID","R2083") -> 5 | H7: =Pivot_summary_restaurants!D7 -> R2083 | J7: =GETPIVOTDATA("Order_value",Pivot_summary_restaurants!$D$5,"Restaurant_ID","R2083") -> 6291 | M7: =Pivot_summary_restaurants!G7 -> R2083 | O7: =GETPIVOTDATA("Restaurant_profit",Pivot_summary_restaurants!$G$5,"Restaurant_ID","R2083") -> 5599 | R7: =Pivot_summary_restaurants!P7 -> R2536 | T7: =GETPIVOTDATA("Delivery_time",Pivot_summary_restaurants!$P$5,"Restaurant_ID","R2536") -> 0.029398148 | W7: =Pivot_summary_restaurants!V7 -> R2334 | Y7: =GETPIVOTDATA("Average",Pivot_summary_restaurants!$V$5,"Restaurant_ID","R2334") -> 133.33333
C8: =Pivot_summary_restaurants!A8 -> R2016 | E8: =GETPIVOTDATA("Restaurant_ID",Pivot_summary_restaurants!$A$5,"Restaurant_ID","R2016") -> 5 | H8: =Pivot_summary_restaurants!D8 -> R2933 | J8: =GETPIVOTDATA("Order_value",Pivot_summary_restaurants!$D$5,"Restaurant_ID","R2933") -> 6049 | M8: =Pivot_summary_restaurants!G8 -> R2933 | O8: =GETPIVOTDATA("Restaurant_profit",Pivot_summary_restaurants!$G$5,"Restaurant_ID","R2933") -> 5547 | R8: =Pivot_summary_restaurants!P8 -> R2267 | T8: =GETPIVOTDATA("Delivery_time",Pivot_summary_restaurants!$P$5,"Restaurant_ID","R2267") -> 0.03125 | W8: =Pivot_summary_restaurants!V8 -> R2287 | Y8: =GETPIVOTDATA("Average",Pivot_summary_restaurants!$V$5,"Restaurant_ID","R2287") -> 100
C9: =Pivot_summary_restaurants!A9 -> R2804 | E9: =GETPIVOTDATA("Restaurant_ID",Pivot_summary_restaurants!$A$5,"Restaurant_ID","R2804") -> 5 | H9: =Pivot_summary_restaurants!D9 -> R2329 | J9: =GETPIVOTDATA("Order_value",Pivot_summary_restaurants!$D$5,"Restaurant_ID","R2329") -> 5398 | M9: =Pivot_summary_restaurants!G9 -> R2329 | O9: =GETPIVOTDATA("Restaurant_profit",Pivot_summary_restaurants!$G$5,"Restaurant_ID","R2329") -> 4894 | R9: =Pivot_summary_restaurants!P9 -> R2454 | T9: =GETPIVOTDATA("Delivery_time",Pivot_summary_restaurants!$P$5,"Restaurant_ID","R2454") -> 0.032638889 | W9: =Pivot_summary_restaurants!V9 -> R2010 | Y9: =GETPIVOTDATA("Average",Pivot_summary_restaurants!$V$5,"Restaurant_ID","R2010") -> 83.333333
C10: =Pivot_summary_restaurants!A10 -> R2726 | E10: =GETPIVOTDATA("Restaurant_ID",Pivot_summary_restaurants!$A$5,"Restaurant_ID","R2726") -> 5 | H10: =Pivot_summary_restaurants!D10 -> R2355 | J10: =GETPIVOTDATA("Order_value",Pivot_summary_restaurants!$D$5,"Restaurant_ID","R2355") -> 5320 | M10: =Pivot_summary_restaurants!G10 -> R2747 | O10: =GETPIVOTDATA("Restaurant_profit",Pivot_summary_restaurants!$G$5,"Restaurant_ID","R2747") -> 4846 | R10: =Pivot_summary_restaurants!P10 -> R2520 | T10: =GETPIVOTDATA("Delivery_time",Pivot_summary_restaurants!$P$5,"Restaurant_ID","R2520") -> 0.032638889 | W10: =Pivot_summary_restaurants!V10 -> R2169 | Y10: =GETPIVOTDATA("Average",Pivot_summary_restaurants!$V$5,"Restaurant_ID","R2169") -> 83.333333
C11: =Pivot_summary_restaurants!A11 -> R2523 | E11: =GETPIVOTDATA("Restaurant_ID",Pivot_summary_restaurants!$A$5,"Restaurant_ID","R2523") -> 5 | H11: * Restaurants' estimates considered only places with at least 3 orders. | W11: =Pivot_summary_restaurants!V11 -> R2816 | Y11: =GETPIVOTDATA("Average",Pivot_summary_restaurants!$V$5,"Restaurant_ID","R2816") -> 83.333333
A15: TOP 5 CLIENTS WHO BOUGHT THE MOST
A16: Client | C16: Total bought
A17: =Pivot_summary_customers!A6 -> C7949 | C17: =GETPIVOTDATA("Total_bought",Pivot_summary_customers!$A$5,"Customer_ID","C7949") -> 3870
A18: =Pivot_summary_customers!A7 -> C3832 | C18: =GETPIVOTDATA("Total_bought",Pivot_summary_customers!$A$5,"Customer_ID","C3832") -> 3768
A19: =Pivot_summary_customers!A8 -> C8266 | C19: =GETPIVOTDATA("Total_bought",Pivot_summary_customers!$A$5,"Customer_ID","C8266") -> 3703
A20: =Pivot_summary_customers!A9 -> C5555 | C20: =GETPIVOTDATA("Total_bought",Pivot_summary_customers!$A$5,"Customer_ID","C5555") -> 3664
A21: =Pivot_summary_customers!A10 -> C5146 | C21: =GETPIVOTDATA("Total_bought",Pivot_summary_customers!$A$5,"Customer_ID","C5146") -> 3361
